2024-09-14 16:43:58,400 INFO    MainThread:20106 [wandb_setup.py:_flush():77] Current SDK version is 0.18.0
2024-09-14 16:43:58,401 INFO    MainThread:20106 [wandb_setup.py:_flush():77] Configure stats pid to 20106
2024-09-14 16:43:58,402 INFO    MainThread:20106 [wandb_setup.py:_flush():77] Loading settings from /Users/chenbaiyan/.config/wandb/settings
2024-09-14 16:43:58,403 INFO    MainThread:20106 [wandb_setup.py:_flush():77] Loading settings from /Users/chenbaiyan/Desktop/ml_test/wandb/settings
2024-09-14 16:43:58,403 INFO    MainThread:20106 [wandb_setup.py:_flush():77] Loading settings from environment variables: {}
2024-09-14 16:43:58,403 INFO    MainThread:20106 [wandb_setup.py:_flush():77] Applying setup settings: {'_disable_service': False}
2024-09-14 16:43:58,403 INFO    MainThread:20106 [wandb_setup.py:_flush():77] Inferring run settings from compute environment: {'program_relpath': 'cases_ml.py', 'program_abspath': '/Users/chenbaiyan/Desktop/ml_test/cases_ml.py', 'program': '/Users/chenbaiyan/Desktop/ml_test/cases_ml.py'}
2024-09-14 16:43:58,403 INFO    MainThread:20106 [wandb_setup.py:_flush():77] Applying login settings: {}
2024-09-14 16:43:58,403 INFO    MainThread:20106 [wandb_init.py:_log_setup():525] Logging user logs to /Users/chenbaiyan/Desktop/ml_test/wandb/run-20240914_164358-8odusk6y/logs/debug.log
2024-09-14 16:43:58,403 INFO    MainThread:20106 [wandb_init.py:_log_setup():526] Logging internal logs to /Users/chenbaiyan/Desktop/ml_test/wandb/run-20240914_164358-8odusk6y/logs/debug-internal.log
2024-09-14 16:43:58,403 INFO    MainThread:20106 [wandb_init.py:init():609] calling init triggers
2024-09-14 16:43:58,403 INFO    MainThread:20106 [wandb_init.py:init():616] wandb.init called with sweep_config: {}
config: {}
2024-09-14 16:43:58,403 INFO    MainThread:20106 [wandb_init.py:init():659] starting backend
2024-09-14 16:43:58,403 INFO    MainThread:20106 [wandb_init.py:init():663] setting up manager
2024-09-14 16:43:58,405 INFO    MainThread:20106 [backend.py:_multiprocessing_setup():105] multiprocessing start_methods=spawn,fork,forkserver, using: spawn
2024-09-14 16:43:58,406 INFO    MainThread:20106 [wandb_init.py:init():671] backend started and connected
2024-09-14 16:43:58,410 INFO    MainThread:20106 [wandb_init.py:init():766] updated telemetry
2024-09-14 16:43:58,411 INFO    MainThread:20106 [wandb_init.py:init():799] communicating run to backend with 90.0 second timeout
2024-09-14 16:43:59,899 INFO    MainThread:20106 [wandb_init.py:init():850] starting run threads in backend
2024-09-14 16:43:59,947 INFO    MainThread:20106 [wandb_run.py:_console_start():2466] atexit reg
2024-09-14 16:43:59,947 INFO    MainThread:20106 [wandb_run.py:_redirect():2312] redirect: wrap_raw
2024-09-14 16:43:59,947 INFO    MainThread:20106 [wandb_run.py:_redirect():2377] Wrapping output streams.
2024-09-14 16:43:59,947 INFO    MainThread:20106 [wandb_run.py:_redirect():2402] Redirects installed.
2024-09-14 16:43:59,949 INFO    MainThread:20106 [wandb_init.py:init():893] run started, returning control to user process
2024-09-14 16:59:43,647 ERROR   MainThread:20106 [util.py:get_module():277] Error importing optional module plotly.tools
Traceback (most recent call last):
  File "/Users/chenbaiyan/Desktop/ml_test/.venv/lib/python3.12/site-packages/wandb/util.py", line 243, in import_module_lazy
    return sys.modules[name]
           ~~~~~~~~~~~^^^^^^
KeyError: 'plotly.tools'

During handling of the above exception, another exception occurred:

Traceback (most recent call last):
  File "/Users/chenbaiyan/Desktop/ml_test/.venv/lib/python3.12/site-packages/wandb/util.py", line 272, in get_module
    return import_module_lazy(name)
           ^^^^^^^^^^^^^^^^^^^^^^^^
  File "/Users/chenbaiyan/Desktop/ml_test/.venv/lib/python3.12/site-packages/wandb/util.py", line 245, in import_module_lazy
    spec = importlib.util.find_spec(name)
           ^^^^^^^^^^^^^^^^^^^^^^^^^^^^^^
  File "<frozen importlib.util>", line 91, in find_spec
ModuleNotFoundError: No module named 'plotly'
2024-09-14 16:59:43,655 WARNING MsgRouterThr:20106 [router.py:message_loop():77] message_loop has been closed
